2024-02-24 21:28:49,014 ERROR: Exception on /reset_password_request [POST] [in /Users/jay/Desktop/project/mento-camp/m3-week-07-jayredk/.venv/lib/python3.11/site-packages/flask/app.py:828]
Traceback (most recent call last):
  File "/Users/jay/Desktop/project/mento-camp/m3-week-07-jayredk/.venv/lib/python3.11/site-packages/flask/app.py", line 1463, in wsgi_app
    response = self.full_dispatch_request()
               ^^^^^^^^^^^^^^^^^^^^^^^^^^^^
  File "/Users/jay/Desktop/project/mento-camp/m3-week-07-jayredk/.venv/lib/python3.11/site-packages/flask/app.py", line 872, in full_dispatch_request
    rv = self.handle_user_exception(e)
         ^^^^^^^^^^^^^^^^^^^^^^^^^^^^^
  File "/Users/jay/Desktop/project/mento-camp/m3-week-07-jayredk/.venv/lib/python3.11/site-packages/flask/app.py", line 870, in full_dispatch_request
    rv = self.dispatch_request()
         ^^^^^^^^^^^^^^^^^^^^^^^
  File "/Users/jay/Desktop/project/mento-camp/m3-week-07-jayredk/.venv/lib/python3.11/site-packages/flask/app.py", line 855, in dispatch_request
    return self.ensure_sync(self.view_functions[rule.endpoint])(**view_args)  # type: ignore[no-any-return]
           ^^^^^^^^^^^^^^^^^^^^^^^^^^^^^^^^^^^^^^^^^^^^^^^^^^^^^^^^^^^^^^^^^
  File "/Users/jay/Desktop/project/mento-camp/m3-week-07-jayredk/microblog/app/routes.py", line 193, in reset_password_request
    send_password_reset_email(user)
  File "/Users/jay/Desktop/project/mento-camp/m3-week-07-jayredk/microblog/app/email.py", line 13, in send_password_reset_email
    send_email('[Microblog] Reset Your Password',
  File "/Users/jay/Desktop/project/mento-camp/m3-week-07-jayredk/microblog/app/email.py", line 9, in send_email
    mail.send(msg)
  File "/Users/jay/Desktop/project/mento-camp/m3-week-07-jayredk/.venv/lib/python3.11/site-packages/flask_mail.py", line 491, in send
    with self.connect() as connection:
  File "/Users/jay/Desktop/project/mento-camp/m3-week-07-jayredk/.venv/lib/python3.11/site-packages/flask_mail.py", line 144, in __enter__
    self.host = self.configure_host()
                ^^^^^^^^^^^^^^^^^^^^^
  File "/Users/jay/Desktop/project/mento-camp/m3-week-07-jayredk/.venv/lib/python3.11/site-packages/flask_mail.py", line 158, in configure_host
    host = smtplib.SMTP(self.mail.server, self.mail.port)
           ^^^^^^^^^^^^^^^^^^^^^^^^^^^^^^^^^^^^^^^^^^^^^^
  File "/Users/jay/.pyenv/versions/3.11.5/lib/python3.11/smtplib.py", line 255, in __init__
    (code, msg) = self.connect(host, port)
                  ^^^^^^^^^^^^^^^^^^^^^^^^
  File "/Users/jay/.pyenv/versions/3.11.5/lib/python3.11/smtplib.py", line 341, in connect
    self.sock = self._get_socket(host, port, self.timeout)
                ^^^^^^^^^^^^^^^^^^^^^^^^^^^^^^^^^^^^^^^^^^
  File "/Users/jay/.pyenv/versions/3.11.5/lib/python3.11/smtplib.py", line 312, in _get_socket
    return socket.create_connection((host, port), timeout,
           ^^^^^^^^^^^^^^^^^^^^^^^^^^^^^^^^^^^^^^^^^^^^^^^
  File "/Users/jay/.pyenv/versions/3.11.5/lib/python3.11/socket.py", line 851, in create_connection
    raise exceptions[0]
  File "/Users/jay/.pyenv/versions/3.11.5/lib/python3.11/socket.py", line 836, in create_connection
    sock.connect(sa)
ConnectionRefusedError: [Errno 61] Connection refused
2024-02-24 21:31:18,204 ERROR: Exception on /reset_password_request [POST] [in /Users/jay/Desktop/project/mento-camp/m3-week-07-jayredk/.venv/lib/python3.11/site-packages/flask/app.py:828]
Traceback (most recent call last):
  File "/Users/jay/Desktop/project/mento-camp/m3-week-07-jayredk/.venv/lib/python3.11/site-packages/flask/app.py", line 1463, in wsgi_app
    response = self.full_dispatch_request()
               ^^^^^^^^^^^^^^^^^^^^^^^^^^^^
  File "/Users/jay/Desktop/project/mento-camp/m3-week-07-jayredk/.venv/lib/python3.11/site-packages/flask/app.py", line 872, in full_dispatch_request
    rv = self.handle_user_exception(e)
         ^^^^^^^^^^^^^^^^^^^^^^^^^^^^^
  File "/Users/jay/Desktop/project/mento-camp/m3-week-07-jayredk/.venv/lib/python3.11/site-packages/flask/app.py", line 870, in full_dispatch_request
    rv = self.dispatch_request()
         ^^^^^^^^^^^^^^^^^^^^^^^
  File "/Users/jay/Desktop/project/mento-camp/m3-week-07-jayredk/.venv/lib/python3.11/site-packages/flask/app.py", line 855, in dispatch_request
    return self.ensure_sync(self.view_functions[rule.endpoint])(**view_args)  # type: ignore[no-any-return]
           ^^^^^^^^^^^^^^^^^^^^^^^^^^^^^^^^^^^^^^^^^^^^^^^^^^^^^^^^^^^^^^^^^
  File "/Users/jay/Desktop/project/mento-camp/m3-week-07-jayredk/microblog/app/routes.py", line 193, in reset_password_request
    send_password_reset_email(user)
  File "/Users/jay/Desktop/project/mento-camp/m3-week-07-jayredk/microblog/app/email.py", line 13, in send_password_reset_email
    send_email('[Microblog] Reset Your Password',
  File "/Users/jay/Desktop/project/mento-camp/m3-week-07-jayredk/microblog/app/email.py", line 9, in send_email
    mail.send(msg)
  File "/Users/jay/Desktop/project/mento-camp/m3-week-07-jayredk/.venv/lib/python3.11/site-packages/flask_mail.py", line 491, in send
    with self.connect() as connection:
  File "/Users/jay/Desktop/project/mento-camp/m3-week-07-jayredk/.venv/lib/python3.11/site-packages/flask_mail.py", line 144, in __enter__
    self.host = self.configure_host()
                ^^^^^^^^^^^^^^^^^^^^^
  File "/Users/jay/Desktop/project/mento-camp/m3-week-07-jayredk/.venv/lib/python3.11/site-packages/flask_mail.py", line 158, in configure_host
    host = smtplib.SMTP(self.mail.server, self.mail.port)
           ^^^^^^^^^^^^^^^^^^^^^^^^^^^^^^^^^^^^^^^^^^^^^^
  File "/Users/jay/.pyenv/versions/3.11.5/lib/python3.11/smtplib.py", line 255, in __init__
    (code, msg) = self.connect(host, port)
                  ^^^^^^^^^^^^^^^^^^^^^^^^
  File "/Users/jay/.pyenv/versions/3.11.5/lib/python3.11/smtplib.py", line 341, in connect
    self.sock = self._get_socket(host, port, self.timeout)
                ^^^^^^^^^^^^^^^^^^^^^^^^^^^^^^^^^^^^^^^^^^
  File "/Users/jay/.pyenv/versions/3.11.5/lib/python3.11/smtplib.py", line 312, in _get_socket
    return socket.create_connection((host, port), timeout,
           ^^^^^^^^^^^^^^^^^^^^^^^^^^^^^^^^^^^^^^^^^^^^^^^
  File "/Users/jay/.pyenv/versions/3.11.5/lib/python3.11/socket.py", line 851, in create_connection
    raise exceptions[0]
  File "/Users/jay/.pyenv/versions/3.11.5/lib/python3.11/socket.py", line 836, in create_connection
    sock.connect(sa)
ConnectionRefusedError: [Errno 61] Connection refused
2024-02-24 21:33:17,948 INFO: Microblog startup [in /Users/jay/Desktop/project/mento-camp/m3-week-07-jayredk/microblog/app/__init__.py:45]
2024-02-24 21:35:46,977 INFO: Microblog startup [in /Users/jay/Desktop/project/mento-camp/m3-week-07-jayredk/microblog/app/__init__.py:45]
2024-02-24 21:36:20,495 INFO: Microblog startup [in /Users/jay/Desktop/project/mento-camp/m3-week-07-jayredk/microblog/app/__init__.py:45]
2024-02-24 21:36:39,220 INFO: Microblog startup [in /Users/jay/Desktop/project/mento-camp/m3-week-07-jayredk/microblog/app/__init__.py:45]
2024-02-24 21:37:29,879 INFO: Microblog startup [in /Users/jay/Desktop/project/mento-camp/m3-week-07-jayredk/microblog/app/__init__.py:45]
